<?xml version='1.0' encoding='utf-8'?>
<robot xmlns:xacro="http://www.ros.org/wiki/xacro" name="panda">
  <xacro:macro name="panda_arm" params="arm_id:='panda' description_pkg:='panda_description' connected_to:='' xyz:='0 0 0' rpy:='0 0 0'">
    <xacro:unless value="${not connected_to}">
      <joint name="${arm_id}_joint_${connected_to}" type="fixed">
        <parent link="${connected_to}"/>
        <child link="${arm_id}_link0"/>
        <origin rpy="${rpy}" xyz="${xyz}"/>
      </joint>
    </xacro:unless>

    <!-- Define constants -->
    <xacro:property name="joint_damping" value="10.0"/>

    <!-- Used for fixing robot to Gazebo 'base_link' -->
    <link name="world"/>

    <joint name="robot_to_world" type="fixed">
      <parent link="world"/>
      <child link="${arm_id}_link0"/>
      <!-- <origin xyz="0.0 0.0 0.0" rpy="0.0 0.0 0.0" /> -->
    </joint>

    <!-- Link 0 -->
    <link name="${arm_id}_link0">
      <visual>
        <geometry>
          <mesh filename="package://${description_pkg}/meshes/visual/link0.dae"/>
        </geometry>
      </visual>

      <collision>
        <geometry>
          <mesh filename="package://${description_pkg}/meshes/collision/link0.stl"/>
        </geometry>
      </collision>

      <inertial>
        <origin xyz="0 0 0" rpy="0 0 0"/>
        <!-- <mass value="3.06"/> -->
        <mass value="4.970684"/>
        <!-- <inertia ixx="0.3" ixy="0.0" ixz="0.0" iyy="0.3" iyz="0.0" izz="0.3"/> -->
        <!-- <inertia ixx="3" ixy="0.0" ixz="0.0" iyy="3" iyz="0.0" izz="3"/> -->
        <!-- <inertia ixx="0.03" ixy="0.0" ixz="0.0" iyy="0.03" iyz="0.0" izz="0.03"/> -->
        <inertia ixx="0.70337" ixy="-0.000139" ixz="0.0067720" iyy="0.70661" iyz="0.019169" izz="0.0091170"/>
      </inertial>
    </link>

    <!-- Joint 1 connects Link 0 and Link 1 -->
    <joint name="${arm_id}_joint1" type="revolute">
      <safety_controller k_position="100.0" k_velocity="40.0" soft_lower_limit="-2.8973" soft_upper_limit="2.8973"/>
      <origin rpy="0 0 0" xyz="0 0 0.333"/>
      <parent link="${arm_id}_link0"/>
      <child link="${arm_id}_link1"/>
      <axis xyz="0 0 1"/>
      <!-- <limit effort="87" lower="-2.8973" upper="2.8973" velocity="2.1750"/> -->
      <limit effort="87" lower="-2.8973" upper="2.8973" velocity="21.750"/>
      <dynamics damping="${joint_damping}"/>
    </joint>

    <!-- Transmission element for Joint 1 -->
    <transmission name="${arm_id}_tran_1">
      <type>transmission_interface/SimpleTransmission</type>
      <joint name="${arm_id}_joint1">
        <hardwareInterface>hardware_interface/EffortJointInterface</hardwareInterface>
      </joint>
      <actuator name="${arm_id}_motor_1">
        <hardwareInterface>hardware_interface/EffortJointInterface</hardwareInterface>
        <mechanicalReduction>1</mechanicalReduction>
      </actuator>
    </transmission>

    <!-- Link 1 -->
    <link name="${arm_id}_link1">
      <visual>
        <geometry>
          <mesh filename="package://${description_pkg}/meshes/visual/link1.dae"/>
        </geometry>
      </visual>

      <collision>
        <geometry>
          <mesh filename="package://${description_pkg}/meshes/collision/link1.stl"/>
        </geometry>
      </collision>

      <inertial>
        <origin xyz="0 0 0" rpy="0 0 0"/>
        <!-- <mass value="2.34"/> -->
        <mass value="0.646926"/>
        <!-- <inertia ixx="0.3" ixy="0.0" ixz="0.0" iyy="0.3" iyz="0.0" izz="0.3"/> -->
        <!-- <inertia ixx="3" ixy="0.0" ixz="0.0" iyy="3" iyz="0.0" izz="3"/> -->
        <!-- <inertia ixx="0.03" ixy="0.0" ixz="0.0" iyy="0.03" iyz="0.0" izz="0.03"/> -->
        <inertia ixx="0.0079620" ixy="-0.003925" ixz="0.010254" iyy="0.02811" iyz="0.00070400" izz="0.025995"/>
      </inertial>
    </link>

    <!-- Joint 2 connects Link 1 and Link 2 -->
    <joint name="${arm_id}_joint2" type="revolute">
      <safety_controller k_position="100.0" k_velocity="40.0" soft_lower_limit="-1.7628" soft_upper_limit="1.7628"/>
      <origin rpy="${-pi/2} 0 0" xyz="0 0 0"/>
      <parent link="${arm_id}_link1"/>
      <child link="${arm_id}_link2"/>
      <axis xyz="0 0 1"/>
      <!-- <limit effort="87" lower="-1.7628" upper="1.7628" velocity="2.1750"/> -->
      <limit effort="87" lower="-1.7628" upper="1.7628" velocity="21.750"/>
      <dynamics damping="${joint_damping}"/>
    </joint>

    <!-- Transmission element for Joint 2 -->
    <transmission name="${arm_id}_tran_2">
      <type>transmission_interface/SimpleTransmission</type>
      <joint name="${arm_id}_joint2">
        <hardwareInterface>hardware_interface/EffortJointInterface</hardwareInterface>
      </joint>
      <actuator name="${arm_id}_motor_2">
        <hardwareInterface>hardware_interface/EffortJointInterface</hardwareInterface>
          <mechanicalReduction>1</mechanicalReduction>
      </actuator>
    </transmission>

    <!-- Link 2 -->
    <link name="${arm_id}_link2">
      <visual>
        <geometry>
          <mesh filename="package://${description_pkg}/meshes/visual/link2.dae"/>
        </geometry>
      </visual>

      <collision>
        <geometry>
          <mesh filename="package://${description_pkg}/meshes/collision/link2.stl"/>
        </geometry>
      </collision>

      <inertial>
        <origin xyz="0 0 0" rpy="0 0 0"/>
        <!-- <mass value="2.36"/> -->
        <mass value="3.228604"/>
        <!-- <inertia ixx="0.3" ixy="0.0" ixz="0.0" iyy="0.3" iyz="0.0" izz="0.3"/> -->
        <!-- <inertia ixx="3" ixy="0.0" ixz="0.0" iyy="3" iyz="0.0" izz="3"/> -->
        <!-- <inertia ixx="0.03" ixy="0.0" ixz="0.0" iyy="0.03" iyz="0.0" izz="0.03"/> -->
        <inertia ixx="0.037242" ixy="-0.0047610" ixz="-0.011396" iyy="0.036155" iyz="-0.012805" izz="0.010830"/>
      </inertial>
    </link>

    <!-- Joint 3 connects Link 2 and Link 3 -->
    <joint name="${arm_id}_joint3" type="revolute">
      <safety_controller k_position="100.0" k_velocity="40.0" soft_lower_limit="-2.8973" soft_upper_limit="2.8973"/>
      <origin rpy="${pi/2} 0 0" xyz="0 -0.316 0"/>
      <parent link="${arm_id}_link2"/>
      <child link="${arm_id}_link3"/>
      <axis xyz="0 0 1"/>
      <!-- <limit effort="87" lower="-2.8973" upper="2.8973" velocity="2.1750"/> -->
      <limit effort="87" lower="-2.8973" upper="2.8973" velocity="21.750"/>
      <dynamics damping="${joint_damping}"/>
    </joint>

    <!-- Transmission element for Joint 3 -->
    <transmission name="${arm_id}_tran_3">
      <type>transmission_interface/SimpleTransmission</type>
      <joint name="${arm_id}_joint3">
        <hardwareInterface>hardware_interface/EffortJointInterface</hardwareInterface>
      </joint>
      <actuator name="${arm_id}_motor_3">
        <hardwareInterface>hardware_interface/EffortJointInterface</hardwareInterface>
        <mechanicalReduction>1</mechanicalReduction>
      </actuator>
    </transmission>

    <!-- Link 3 -->
    <link name="${arm_id}_link3">
      <visual>
        <geometry>
          <mesh filename="package://${description_pkg}/meshes/visual/link3.dae"/>
        </geometry>
      </visual>

      <collision>
        <geometry>
          <mesh filename="package://${description_pkg}/meshes/collision/link3.stl"/>
        </geometry>
      </collision>

      <inertial>
        <origin xyz="0 0 0" rpy="0 0 0"/>
        <!-- <mass value="2.38"/> -->
        <mass value="3.587895"/>
        <!-- <inertia ixx="0.3" ixy="0.0" ixz="0.0" iyy="0.3" iyz="0.0" izz="0.3"/> -->
        <!-- <inertia ixx="3" ixy="0.0" ixz="0.0" iyy="3" iyz="0.0" izz="3"/> -->
        <!-- <inertia ixx="0.03" ixy="0.0" ixz="0.0" iyy="0.03" iyz="0.0" izz="0.03"/> -->
        <inertia ixx="0.025853" ixy="0.007796" ixz="-0.001332" iyy="0.019552" iyz="0.008641" izz="0.028323"/>
      </inertial>
    </link>

    <!-- Joint 4 connects Link 3 and Link 4 -->
    <joint name="${arm_id}_joint4" type="revolute">
      <safety_controller k_position="100.0" k_velocity="40.0" soft_lower_limit="-3.0718" soft_upper_limit="-0.0698"/>
      <origin rpy="${pi/2} 0 0" xyz="0.0825 0 0"/>
      <parent link="${arm_id}_link3"/>
      <child link="${arm_id}_link4"/>
      <axis xyz="0 0 1"/>
      <!-- <limit effort="87" lower="-3.0718" upper="-0.0698" velocity="2.1750"/> -->
      <limit effort="87" lower="-3.0718" upper="-0.0698" velocity="21.750"/>
      <dynamics damping="${joint_damping}"/>
    </joint>

    <!-- Transmission element for Joint 4 -->
    <transmission name="${arm_id}_tran_4">
      <type>transmission_interface/SimpleTransmission</type>
      <joint name="${arm_id}_joint4">
        <hardwareInterface>hardware_interface/EffortJointInterface</hardwareInterface>
      </joint>
      <actuator name="${arm_id}_motor_4">
        <hardwareInterface>hardware_interface/EffortJointInterface</hardwareInterface>
        <mechanicalReduction>1</mechanicalReduction>
      </actuator>
    </transmission>

    <!-- Link 4 -->
    <link name="${arm_id}_link4">
      <visual>
        <geometry>
          <mesh filename="package://${description_pkg}/meshes/visual/link4.dae"/>
        </geometry>
      </visual>

      <collision>
        <geometry>
          <mesh filename="package://${description_pkg}/meshes/collision/link4.stl"/>
        </geometry>
      </collision>

      <inertial>
        <origin xyz="0 0 0" rpy="0 0 0"/>
        <!-- <mass value="2.43"/> -->
        <mass value="1.225946"/>
        <!-- <inertia ixx="0.3" ixy="0.0" ixz="0.0" iyy="0.3" iyz="0.0" izz="0.3"/> -->
        <!-- <inertia ixx="3" ixy="0.0" ixz="0.0" iyy="3" iyz="0.0" izz="3"/> -->
        <!-- <inertia ixx="0.03" ixy="0.0" ixz="0.0" iyy="0.03" iyz="0.0" izz="0.03"/> -->
        <inertia ixx="0.035549" ixy="-0.002117" ixz="-0.004038" iyy="0.029474" iyz="0.000229" izz="0.008627"/>
      </inertial>
    </link>

    <!-- Joint 5 connects Link 4 and Link 5 -->
    <joint name="${arm_id}_joint5" type="revolute">
      <safety_controller k_position="100.0" k_velocity="40.0" soft_lower_limit="-2.8973" soft_upper_limit="2.8973"/>
      <origin rpy="${-pi/2} 0 0" xyz="-0.0825 0.384 0"/>
      <parent link="${arm_id}_link4"/>
      <child link="${arm_id}_link5"/>
      <axis xyz="0 0 1"/>
      <!-- <limit effort="12" lower="-2.8973" upper="2.8973" velocity="2.6100"/> -->
      <limit effort="12" lower="-2.8973" upper="2.8973" velocity="26.100"/>
      <dynamics damping="${joint_damping}"/>
    </joint>

    <!-- Transmission element for Joint 5 -->
    <transmission name="${arm_id}_tran_5">
      <type>transmission_interface/SimpleTransmission</type>
      <joint name="${arm_id}_joint5">
        <hardwareInterface>hardware_interface/EffortJointInterface</hardwareInterface>
      </joint>
      <actuator name="${arm_id}_motor_5">
        <hardwareInterface>hardware_interface/EffortJointInterface</hardwareInterface>
        <mechanicalReduction>1</mechanicalReduction>
      </actuator>
    </transmission>

    <!-- Link 5 -->
    <link name="${arm_id}_link5">
      <visual>
        <geometry>
          <mesh filename="package://${description_pkg}/meshes/visual/link5.dae"/>
        </geometry>
      </visual>

      <collision>
        <geometry>
          <mesh filename="package://${description_pkg}/meshes/collision/link5.stl"/>
        </geometry>
      </collision>

      <inertial>
        <origin xyz="0 0 0" rpy="0 0 0"/>
        <!-- <mass value="3.5"/> -->
        <mass value="1.666555"/>
        <!-- <inertia ixx="0.3" ixy="0.0" ixz="0.0" iyy="0.3" iyz="0.0" izz="0.3"/> -->
        <!-- <inertia ixx="3" ixy="0.0" ixz="0.0" iyy="3" iyz="0.0" izz="3"/> -->
        <!-- <inertia ixx="0.03" ixy="0.0" ixz="0.0" iyy="0.03" iyz="0.0" izz="0.03"/> -->
        <inertia ixx="0.001964" ixy="0.000109" ixz="-0.001158" iyy="0.004354" iyz="0.003410" izz="0.005433"/>
      </inertial>
    </link>

    <!-- Joint 6 connects Link 5 and Link 6 -->
    <joint name="${arm_id}_joint6" type="revolute">
      <safety_controller k_position="100.0" k_velocity="40.0" soft_lower_limit="-0.0175" soft_upper_limit="3.7525"/>
      <origin rpy="${pi/2} 0 0" xyz="0 0 0"/>
      <parent link="${arm_id}_link5"/>
      <child link="${arm_id}_link6"/>
      <axis xyz="0 0 1"/>
      <!-- <limit effort="12" lower="-0.0175" upper="3.7525" velocity="2.6100"/> -->
      <limit effort="12" lower="-0.0175" upper="3.7525" velocity="26.100"/>
      <dynamics damping="${joint_damping}"/>
    </joint>

    <!-- Transmission element for Joint 6 -->
    <transmission name="${arm_id}_tran_6">
      <type>transmission_interface/SimpleTransmission</type>
      <joint name="${arm_id}_joint6">
        <hardwareInterface>hardware_interface/EffortJointInterface</hardwareInterface>
      </joint>
      <actuator name="${arm_id}_motor_6">
        <hardwareInterface>hardware_interface/EffortJointInterface</hardwareInterface>
        <mechanicalReduction>1</mechanicalReduction>
      </actuator>
    </transmission>

    <!-- Link 6 -->
    <link name="${arm_id}_link6">
      <visual>
        <geometry>
          <mesh filename="package://${description_pkg}/meshes/visual/link6.dae"/>
        </geometry>
      </visual>

      <collision>
        <geometry>
          <mesh filename="package://${description_pkg}/meshes/collision/link6.stl"/>
        </geometry>
      </collision>

      <inertial>
        <origin xyz="0 0 0" rpy="0 0 0"/>
        <!-- <mass value="1.47"/> -->
        <mass value="0.735522"/>
        <!-- <inertia ixx="0.3" ixy="0.0" ixz="0.0" iyy="0.3" iyz="0.0" izz="0.3"/> -->
        <!-- <inertia ixx="3" ixy="0.0" ixz="0.0" iyy="3" iyz="0.0" izz="3"/> -->
        <!-- <inertia ixx="0.03" ixy="0.0" ixz="0.0" iyy="0.03" iyz="0.0" izz="0.03"/> -->
        <inertia ixx="0.012516" ixy="-0.000428" ixz="-0.001196" iyy="0.010027" iyz="-0.000741" izz="0.00048150"/>
      </inertial>
    </link>

    <!-- Joint 7 connects Link 6 and Link 7 -->
    <joint name="${arm_id}_joint7" type="revolute">
      <safety_controller k_position="100.0" k_velocity="40.0" soft_lower_limit="-2.8973" soft_upper_limit="2.8973"/>
      <origin rpy="${pi/2} 0 0" xyz="0.088 0 0"/>
      <parent link="${arm_id}_link6"/>
      <child link="${arm_id}_link7"/>
      <axis xyz="0 0 1"/>
      <!-- <limit effort="12" lower="-2.8973" upper="2.8973" velocity="2.6100"/> -->
      <limit effort="12" lower="-2.8973" upper="2.8973" velocity="26.100"/>
      <dynamics damping="${joint_damping}"/>
    </joint>

    <!-- Transmission element for Joint 7 -->
    <transmission name="${arm_id}_tran_7">
      <type>transmission_interface/SimpleTransmission</type>
      <joint name="${arm_id}_joint7">
        <hardwareInterface>hardware_interface/EffortJointInterface</hardwareInterface>
      </joint>
      <actuator name="${arm_id}_motor_7">
        <hardwareInterface>hardware_interface/EffortJointInterface</hardwareInterface>
        <mechanicalReduction>1</mechanicalReduction>
      </actuator>
    </transmission>
    
    <!-- Link 7 -->
    <link name="${arm_id}_link7">
      <visual>
        <geometry>
          <mesh filename="package://${description_pkg}/meshes/visual/link7.dae"/>
        </geometry>
      </visual>

      <collision>
        <geometry>
          <mesh filename="package://${description_pkg}/meshes/collision/link7.stl"/>
        </geometry>
      </collision>

      <inertial>
        <origin xyz="0 0 0" rpy="0 0 0"/>
        <mass value="0.45"/>
        <inertia ixx="0.3" ixy="0.0" ixz="0.0" iyy="0.3" iyz="0.0" izz="0.3"/>
        <!-- <inertia ixx="3" ixy="0.0" ixz="0.0" iyy="3" iyz="0.0" izz="3"/> -->
        <!-- <inertia ixx="0.03" ixy="0.0" ixz="0.0" iyy="0.03" iyz="0.0" izz="0.03"/> -->
      </inertial>
    </link>

    <!-- Joint to connect Link 7 and Link 8 -->
    <joint name="${arm_id}_joint8" type="fixed">
      <origin rpy="0 0 0" xyz="0 0 0.107"/>
      <parent link="${arm_id}_link7"/>
      <child link="${arm_id}_link8"/>
      <axis xyz="0 0 0"/>
    </joint>

    <!-- Link 8 -->
    <link name="${arm_id}_link8">
    <inertial>
        <origin xyz="0 0 0" rpy="0 0 0"/>
        <mass value="0.0"/>
        <inertia ixx="0.3" ixy="0.0" ixz="0.0" iyy="0.3" iyz="0.0" izz="0.3"/>
      </inertial>
    </link>

  </xacro:macro>
</robot>
